Workbook

Sheet SharePoint Export
A1: Nr | B1: Customer | C1: Project document library | D1: Legal entity | E1: Industry | F1: Project status | G1: Started at | H1: Closed at | I1: PM | J1: PP | K1: PA | L1: Services | M1: Financing type | N1: Quotation Number | O1: CapEx | P1: IPS fees | Q1: Project start year | R1: Project close year | S1: Reference Sheet link | T1: ID | U1: Teams Site | V1: Item Type | W1: Path | X1: Project Status Check | Y1: PM Check | Z1: Pilot Check | AA1: Exclude | AB1: Project Status Align | AC1: PM Align | AD1: Pilot Align
A2: O3581 | B2: GOPA | C2: EM4897_BESS Project | D2: IAPS Tunisia | E2: Chemicals | F2: Work in progress | G2: 46098.042 | I2: Wissem Bensaid | J2: Wissem Bensaid | L2: Project Management;#1;#Engineering;#7;#HVAC Engineering;#14;#Utilities Engineering;#19 | M2: Lump sum | N2: Q9253 | O2: 0 | P2: 172000 | Q2: 2026 | T2: 2963 | U2: O3581 GOPA EM4897_BESS Project | V2: Item | W2: sites/Activity/Lists/GroupIPSProjects | X2: =VLOOKUP(Table_query__64[[#This Row],[Nr]],'MyTracker Export'!A:P,'MyTracker Export'!$P$1,FALSE) -> Work in progress | Y2: =VLOOKUP(Table_query__64[[#This Row],[Nr]],'MyTracker Export'!A:Z,'MyTracker Export'!$Z$1,FALSE) -> Istabrak Frikha | Z2: =VLOOKUP(Table_query__64[[#This Row],[Nr]],'MyTracker Export'!A:AA,'MyTracker Export'!$AA$1,FALSE) -> Wissem Bensaid | AB2: =IF(Table_query__64[[#This Row],[Project status]]=Table_query__64[[#This Row],[Project Status Check]],"OK","NOK") -> OK | AC2: =IF(Table_query__64[[#This Row],[PM]]=Table_query__64[[#This Row],[PM Check]],"OK","NOK") -> NOK | AD2: =IF(Table_query__64[[#This Row],[PP]]=Table_query__64[[#This Row],[Pilot Check]],"OK","NOK") -> OK
A3: O3580 | B3: Cargill Chocolate Belgium NV (Mouscron) | C3: P&ID Update Nuts connection | D3: IPS Belgium | E3: Food & Beverages | F3: Work in progress | G3: 46098.042 | I3: Audric Jeanne | J3: Karel De Swert | L3: Project Management;#1;#Engineering;#7 | M3: Lump sum | N3: Q9213 | O3: 10000 | P3: 828.09 | Q3: 2026 | T3: 2962 | U3: O3580 Cargill P&ID Update Nuts connection | V3: Item | W3: sites/Activity/Lists/GroupIPSProjects | X3: =VLOOKUP(Table_query__64[[#This Row],[Nr]],'MyTracker Export'!A:P,'MyTracker Export'!$P$1,FALSE) -> Work in progress | Y3: =VLOOKUP(Table_query__64[[#This Row],[Nr]],'MyTracker Export'!A:Z,'MyTracker Export'!$Z$1,FALSE) -> Audric Jeanne | Z3: =VLOOKUP(Table_query__64[[#This Row],[Nr]],'MyTracker Export'!A:AA,'MyTracker Export'!$AA$1,FALSE) -> Karel De Swert | AB3: =IF(Table_query__64[[#This Row],[Project status]]=Table_query__64[[#This Row],[Project Status Check]],"OK","NOK") -> OK | AC3: =IF(Table_query__64[[#This Row],[PM]]=Table_query__64[[#This Row],[PM Check]],"OK","NOK") -> OK | AD3: =IF(Table_query__64[[#This Row],[PP]]=Table_query__64[[#This Row],[Pilot Check]],"OK","NOK") -> OK
A4: O3579 | B4: BLIP | C4: BLIP OFFICES | D4: Arquid | E4: Buildings | F4: Work in progress | G4: 46097.042 | I4: Laura Cestau | J4: Laura Cestau | L4: Project Management;#1;#Architecture;#5 | M4: Lump sum | N4: Q9076 | O4: 20 | P4: 33957 | Q4: 2026 | T4: 2961 | U4: O3579 BLIP BLIP OFFICES | V4: Item | W4: sites/Activity/Lists/GroupIPSProjects | X4: =VLOOKUP(Table_query__64[[#This Row],[Nr]],'MyTracker Export'!A:P,'MyTracker Export'!$P$1,FALSE) -> Work in progress | Y4: =VLOOKUP(Table_query__64[[#This Row],[Nr]],'MyTracker Export'!A:Z,'MyTracker Export'!$Z$1,FALSE) -> Laura Cestau | Z4: =VLOOKUP(Table_query__64[[#This Row],[Nr]],'MyTracker Export'!A:AA,'MyTracker Export'!$AA$1,FALSE) -> Laura Cestau | AB4: =IF(Table_query__64[[#This Row],[Project status]]=Table_query__64[[#This Row],[Project Status Check]],"OK","NOK") -> OK | AC4: =IF(Table_query__64[[#This Row],[PM]]=Table_query__64[[#This Row],[PM Check]],"OK","NOK") -> OK | AD4: =IF(Table_query__64[[#This Row],[PP]]=Table_query__64[[#This Row],[Pilot Check]],"OK","NOK") -> OK
A5: O3578 | B5: TPS | C5: EM4549_Guebiba water | D5: IAPS Tunisia | E5: Chemicals | F5: Work in progress | G5: 46093.042 | I5: Wissem Bensaid | J5: Wissem Bensaid | L5: Project Management;#1;#Engineering;#7;#Mechanical Engineering;#15;#Piping Engineering;#16;#Process Engineering;#17 | M5: Lump sum | N5: Q9247 | O5: 0 | P5: 88827.9 | Q5: 2026 | T5: 2960 | U5: O3578 TPS EM4549_Guebiba water | V5: Item | W5: sites/Activity/Lists/GroupIPSProjects | X5: =VLOOKUP(Table_query__64[[#This Row],[Nr]],'MyTracker Export'!A:P,'MyTracker Export'!$P$1,FALSE) -> Work in progress | Y5: =VLOOKUP(Table_query__64[[#This Row],[Nr]],'MyTracker Export'!A:Z,'MyTracker Export'!$Z$1,FALSE) -> Anouar Trigui | Z5: =VLOOKUP(Table_query__64[[#This Row],[Nr]],'MyTracker Export'!A:AA,'MyTracker Export'!$AA$1,FALSE) -> Wissem Bensaid | AB5: =IF(Table_query__64[[#This Row],[Project status]]=Table_query__64[[#This Row],[Project Status Check]],"OK","NOK") -> OK | AC5: =IF(Table_query__64[[#This Row],[PM]]=Table_query__64[[#This Row],[PM Check]],"OK","NOK") -> NOK | AD5: =IF(Table_query__64[[#This Row],[PP]]=Table_query__64[[#This Row],[Pilot Check]],"OK","NOK") -> OK
A6: O3577 | B6: Ab InBev EU HQ (BEL Leuven) | C6: Magor Land Conversion | D6: Group-IPS | E6: Food & Beverages | F6: Work in progress | G6: 46093.042 | I6: Natalia Martínez Nieto | J6: Natalia Martínez Nieto | L6: Architecture;#5 | M6: Lump sum | N6: Q9240 | O6: 0 | P6: 4492.65 | Q6: 2026 | T6: 2959 | U6: O3577 Ab InBev Magor Land Conversion | V6: Item | W6: sites/Activity/Lists/GroupIPSProjects | X6: =VLOOKUP(Table_query__64[[#This Row],[Nr]],'MyTracker Export'!A:P,'MyTracker Export'!$P$1,FALSE) -> Work in progress | Y6: =VLOOKUP(Table_query__64[[#This Row],[Nr]],'MyTracker Export'!A:Z,'MyTracker Export'!$Z$1,FALSE) -> Natalia Martínez Nieto | Z6: =VLOOKUP(Table_query__64[[#This Row],[Nr]],'MyTracker Export'!A:AA,'MyTracker Export'!$AA$1,FALSE) -> Natalia Martínez Nieto | AB6: =IF(Table_query__64[[#This Row],[Project status]]=Table_query__64[[#This Row],[Project Status Check]],"OK","NOK") -> OK | AC6: =IF(Table_query__64[[#This Row],[PM]]=Table_query__64[[#This Row],[PM Check]],"OK","NOK") -> OK | AD6: =IF(Table_query__64[[#This Row],[PP]]=Table_query__64[[#This Row],[Pilot Check]],"OK","NOK") -> OK
A7: O3576 | B7: Affinity Factory Italy | C7: Affinity Petcare CGM_STB | D7: IPS Spain | E7: Food & Beverages | F7: Work in progress | G7: 46090.042 | I7: Maria Bonaccio | J7: Maria Bonaccio | L7: Project Management;#1 | M7: Reimbursable | N7: Q9151 | O7: 500000 | P7: 155932.13 | Q7: 2026 | T7: 2958 | U7: O3576 Affinity Factory Italy Affinity Petcare CGM_STB | V7: Item | W7: sites/Activity/Lists/GroupIPSProjects | X7: =VLOOKUP(Table_query__64[[#This Row],[Nr]],'MyTracker Export'!A:P,'MyTracker Export'!$P$1,FALSE) -> Work in progress | Y7: =VLOOKUP(Table_query__64[[#This Row],[Nr]],'MyTracker Export'!A:Z,'MyTracker Export'!$Z$1,FALSE) -> Maria Bonaccio | Z7: =VLOOKUP(Table_query__64[[#This Row],[Nr]],'MyTracker Export'!A:AA,'MyTracker Export'!$AA$1,FALSE) -> Maria Bonaccio | AB7: =IF(Table_query__64[[#This Row],[Project status]]=Table_query__64[[#This Row],[Project Status Check]],"OK","NOK") -> OK | AC7: =IF(Table_query__64[[#This Row],[PM]]=Table_query__64[[#This Row],[PM Check]],"OK","NOK") -> OK | AD7: =IF(Table_query__64[[#This Row],[PP]]=Table_query__64[[#This Row],[Pilot Check]],"OK","NOK") -> OK
A8: O3575 | B8: Albioma | C8: Logistics / Customs | D8: IPS France | E8: Chemicals | F8: Work in progress | G8: 46090.042 | I8: Maria Romero | J8: Josué Silverio | K8: Salma Gueblaoui | L8: Consulting;#2;#Masterplan;#66 | M8: Reimbursable | N8: Q9118 | O8: 350 | P8: 15876 | Q8: 2026 | T8: 2956 | U8: O3575 Albioma Logistics Customs | V8: Item | W8: sites/Activity/Lists/GroupIPSProjects | X8: =VLOOKUP(Table_query__64[[#This Row],[Nr]],'MyTracker Export'!A:P,'MyTracker Export'!$P$1,FALSE) -> Work in progress | Y8: =VLOOKUP(Table_query__64[[#This Row],[Nr]],'MyTracker Export'!A:Z,'MyTracker Export'!$Z$1,FALSE) -> Maria Romero | Z8: =VLOOKUP(Table_query__64[[#This Row],[Nr]],'MyTracker Export'!A:AA,'MyTracker Export'!$AA$1,FALSE) -> Josué Silverio | AB8: =IF(Table_query__64[[#This Row],[Project status]]=Table_query__64[[#This Row],[Project Status Check]],"OK","NOK") -> OK | AC8: =IF(Table_query__64[[#This Row],[PM]]=Table_query__64[[#This Row],[PM Check]],"OK","NOK") -> OK | AD8: =IF(Table_query__64[[#This Row],[PP]]=Table_query__64[[#This Row],[Pilot Check]],"OK","NOK") -> OK
A9: O3574 | B9: InBev Belgium BV | C9: Leuven WH roof renovation | D9: IPS Belgium | E9: Food & Beverages | F9: Work in progress | G9: 46087.042 | I9: Valérie Codesido | J9: Lucas Soto Alonso | L9: Architecture;#5;#Engineering;#7;#Utilities Engineering;#19 | M9: Lump sum | N9: Q9236 | O9: 1.7 | P9: 25725.73 | Q9: 2026 | T9: 2955 | U9: O3574 InBev Belgium BV Leuven WH roof renovation | V9: Item | W9: sites/Activity/Lists/GroupIPSProjects | X9: =VLOOKUP(Table_query__64[[#This Row],[Nr]],'MyTracker Export'!A:P,'MyTracker Export'!$P$1,FALSE) -> Work in progress | Y9: =VLOOKUP(Table_query__64[[#This Row],[Nr]],'MyTracker Export'!A:Z,'MyTracker Export'!$Z$1,FALSE) -> Valérie Codesido | Z9: =VLOOKUP(Table_query__64[[#This Row],[Nr]],'MyTracker Export'!A:AA,'MyTracker Export'!$AA$1,FALSE) -> Lucas Soto | AB9: =IF(Table_query__64[[#This Row],[Project status]]=Table_query__64[[#This Row],[Project Status Check]],"OK","NOK") -> OK | AC9: =IF(Table_query__64[[#This Row],[PM]]=Table_query__64[[#This Row],[PM Check]],"OK","NOK") -> OK | AD9: =IF(Table_query__64[[#This Row],[PP]]=Table_query__64[[#This Row],[Pilot Check]],"OK","NOK") -> NOK
A10: O3573 | B10: GlaxoSmithKline Biologicals Rixensart | C10: GSK RX86 - BoD | D10: IPS Belgium | E10: Life Sciences | F10: Work in progress | G10: 46087 | I10: Mathias Martin | J10: Yves Debaisieux | K10: Céline Lechado | L10: Project Management;#1;#Engineering;#7;#Process Engineering;#17;#Utilities Engineering;#19;#Construction Management;#42;#Engineering Coordination;#54;#Project Assistance;#73;#Safety & Site Supervision;#78 | M10: Lump sum | N10: Q9070 | O10: 1 | P10: 123937 | Q10: 2026 | T10: 2954 | U10: O3573 GlaxoSmithKline GSK RX86 - BoD | V10: Item | W10: sites/Activity/Lists/GroupIPSProjects | X10: =VLOOKUP(Table_query__64[[#This Row],[Nr]],'MyTracker Export'!A:P,'MyTracker Export'!$P$1,FALSE) -> Work in progress | Y10: =VLOOKUP(Table_query__64[[#This Row],[Nr]],'MyTracker Export'!A:Z,'MyTracker Export'!$Z$1,FALSE) -> Mathias Martin | Z10: =VLOOKUP(Table_query__64[[#This Row],[Nr]],'MyTracker Export'!A:AA,'MyTracker Export'!$AA$1,FALSE) -> Yves Debaisieux | AB10: =IF(Table_query__64[[#This Row],[Project status]]=Table_query__64[[#This Row],[Project Status Check]],"OK","NOK") -> OK | AC10: =IF(Table_query__64[[#This Row],[PM]]=Table_query__64[[#This Row],[PM Check]],"OK","NOK") -> OK | AD10: =IF(Table_query__64[[#This Row],[PP]]=Table_query__64[[#This Row],[Pilot Check]],"OK","NOK") -> OK
A11: O3572 | B11: Tennant Solutions | C11: Facility Single Line Diagram | D11: IPS USA | E11: Primary & Metals | F11: Work in progress | G11: 46085.042 | I11: Pranay Pawar | J11: Pranay Pawar | L11: Engineering;#7 | M11: Lump sum | N11: Q9082 | O11: 0.01 | P11: 15454 | Q11: 2026 | T11: 2953 | U11: O3572 Tennant Solutions Facility Single Line Diagram | V11: Item | W11: sites/Activity/Lists/GroupIPSProjects | X11: =VLOOKUP(Table_query__64[[#This Row],[Nr]],'MyTracker Export'!A:P,'MyTracker Export'!$P$1,FALSE) -> Work in progress | Y11: =VLOOKUP(Table_query__64[[#This Row],[Nr]],'MyTracker Export'!A:Z,'MyTracker Export'!$Z$1,FALSE) -> Pranay Pawar | Z11: =VLOOKUP(Table_query__64[[#This Row],[Nr]],'MyTracker Export'!A:AA,'MyTracker Export'!$AA$1,FALSE) -> Pranay Pawar | AB11: =IF(Table_query__64[[#This Row],[Project status]]=Table_query__64[[#This Row],[Project Status Check]],"OK","NOK") -> OK | AC11: =IF(Table_query__64[[#This Row],[PM]]=Table_query__64[[#This Row],[PM Check]],"OK","NOK") -> OK | AD11: =IF(Table_query__64[[#This Row],[PP]]=Table_query__64[[#This Row],[Pilot Check]],"OK","NOK") -> OK
A12: O3571 | B12: Eberspaecher Bulgaria | C12: EBS_Plot EPCM services | D12: IPS Bulgaria | E12: Buildings | F12: Work in progress | G12: 46085.042 | I12: Nevena Banova | J12: Nevena Banova | L12: Project Management;#1;#Engineering;#7;#Construction Management;#42 | M12: Lump sum | N12: Q8653 | O12: 0 | P12: 4780 | Q12: 2026 | T12: 2952 | U12: O3571 Eberspaecher Bulgaria EBS_Plot EPCM services | V12: Item | W12: sites/Activity/Lists/GroupIPSProjects | X12: =VLOOKUP(Table_query__64[[#This Row],[Nr]],'MyTracker Export'!A:P,'MyTracker Export'!$P$1,FALSE) -> Work in progress | Y12: =VLOOKUP(Table_query__64[[#This Row],[Nr]],'MyTracker Export'!A:Z,'MyTracker Export'!$Z$1,FALSE) -> Nevena Banova | Z12: =VLOOKUP(Table_query__64[[#This Row],[Nr]],'MyTracker Export'!A:AA,'MyTracker Export'!$AA$1,FALSE) -> Nevena Banova | AB12: =IF(Table_query__64[[#This Row],[Project status]]=Table_query__64[[#This Row],[Project Status Check]],"OK","NOK") -> OK | AC12: =IF(Table_query__64[[#This Row],[PM]]=Table_query__64[[#This Row],[PM Check]],"OK","NOK") -> OK | AD12: =IF(Table_query__64[[#This Row],[PP]]=Table_query__64[[#This Row],[Pilot Check]],"OK","NOK") -> OK
A13: O3570 | B13: Ab InBev EU HQ (BEL Leuven) | C13: Highbay Extension Leuven | D13: IPS Belgium | E13: Food & Beverages | F13: Work in progress | G13: 46085.042 | I13: Karel De Swert | J13: Karel De Swert | L13: Project Management;#1;#Consulting;#2;#Architecture;#5;#Engineering;#7;#Masterplan;#66 | M13: Lump sum | N13: Q9176 | O13: 0 | P13: 25046.95 | Q13: 2026 | T13: 2951 | U13: O3570 Ab InBev Highbay Extension Leuven | V13: Item | W13: sites/Activity/Lists/GroupIPSProjects | X13: =VLOOKUP(Table_query__64[[#This Row],[Nr]],'MyTracker Export'!A:P,'MyTracker Export'!$P$1,FALSE) -> Work in progress | Y13: =VLOOKUP(Table_query__64[[#This Row],[Nr]],'MyTracker Export'!A:Z,'MyTracker Export'!$Z$1,FALSE) -> Karel De Swert | Z13: =VLOOKUP(Table_query__64[[#This Row],[Nr]],'MyTracker Export'!A:AA,'MyTracker Export'!$AA$1,FALSE) -> Karel De Swert | AB13: =IF(Table_query__64[[#This Row],[Project status]]=Table_query__64[[#This Row],[Project Status Check]],"OK","NOK") -> OK | AC13: =IF(Table_query__64[[#This Row],[PM]]=Table_query__64[[#This Row],[PM Check]],"OK","NOK") -> OK | AD13: =IF(Table_query__64[[#This Row],[PP]]=Table_query__64[[#This Row],[Pilot Check]],"OK","NOK") -> OK
A14: O3569 | B14: Fertinagro | C14: EM4817_Safi TSP Plant | D14: IAPS Tunisia | E14: Chemicals | F14: Work in progress | G14: 46085.042 | I14: Wissem Bensaid | J14: Wissem Bensaid | L14: Project Management;#1 | M14: Lump sum | N14: Q9223 | O14: 0 | P14: 264000 | Q14: 2026 | T14: 2950 | U14: O3569 Fertinagro EM4817_Safi TSP Plant | V14: Item | W14: sites/Activity/Lists/GroupIPSProjects | X14: =VLOOKUP(Table_query__64[[#This Row],[Nr]],'MyTracker Export'!A:P,'MyTracker Export'!$P$1,FALSE) -> Work in progress | Y14: =VLOOKUP(Table_query__64[[#This Row],[Nr]],'MyTracker Export'!A:Z,'MyTracker Export'!$Z$1,FALSE) -> Souhail WALI | Z14: =VLOOKUP(Table_query__64[[#This Row],[Nr]],'MyTracker Export'!A:AA,'MyTracker Export'!$AA$1,FALSE) -> Wissem Bensaid | AB14: =IF(Table_query__64[[#This Row],[Project status]]=Table_query__64[[#This Row],[Project Status Check]],"OK","NOK") -> OK | AC14: =IF(Table_query__64[[#This Row],[PM]]=Table_query__64[[#This Row],[PM Check]],"OK","NOK") -> NOK | AD14: =IF(Table_query__64[[#This Row],[PP]]=Table_query__64[[#This Row],[Pilot Check]],"OK","NOK") -> OK
A15: O3568 | B15: Servicoop Management SL | C15: Cooperativa de Vivienda | D15: Arquid | E15: Buildings | F15: Work in progress | G15: 46084.042 | I15: Jaime ÁLVAREZ PÉREZ | J15: Felipe Langa Hernáez | L15: Project Management;#1;#Architecture;#5;#Engineering;#7;#Utilities Engineering;#19 | M15: Lump sum | N15: Q9130 | O15: 5 | P15: 151188.6 | Q15: 2026 | T15: 2949 | U15: O3568 Servicoop Management SL Cooperativa de Vivienda | V15: Item | W15: sites/Activity/Lists/GroupIPSProjects | X15: =VLOOKUP(Table_query__64[[#This Row],[Nr]],'MyTracker Export'!A:P,'MyTracker Export'!$P$1,FALSE) -> Work in progress | Y15: =VLOOKUP(Table_query__64[[#This Row],[Nr]],'MyTracker Export'!A:Z,'MyTracker Export'!$Z$1,FALSE) -> Jaime Álvarez Pérez | Z15: =VLOOKUP(Table_query__64[[#This Row],[Nr]],'MyTracker Export'!A:AA,'MyTracker Export'!$AA$1,FALSE) -> Felipe Langa Hernáez | AB15: =IF(Table_query__64[[#This Row],[Project status]]=Table_query__64[[#This Row],[Project Status Check]],"OK","NOK") -> OK | AC15: =IF(Table_query__64[[#This Row],[PM]]=Table_query__64[[#This Row],[PM Check]],"OK","NOK") -> OK | AD15: =IF(Table_query__64[[#This Row],[PP]]=Table_query__64[[#This Row],[Pilot Check]],"OK","NOK") -> OK
A16: O3567 | B16: Fertinagro | C16: EM4723_Storage & Pipeline | D16: IAPS Tunisia | E16: Chemicals | F16: Work in progress | G16: 46084.042 | I16: Wissem Bensaid | J16: Wissem Bensaid | L16: Project Management;#1;#Engineering;#7;#Piping Engineering;#16;#Process Engineering;#17 | M16: Lump sum | N16: Q9220 | O16: 0 | P16: 66420 | Q16: 2026 | T16: 2948 | U16: O3567 Fertinagro EM4723_Storage & Pipeline | V16: Item | W16: sites/Activity/Lists/GroupIPSProjects | X16: =VLOOKUP(Table_query__64[[#This Row],[Nr]],'MyTracker Export'!A:P,'MyTracker Export'!$P$1,FALSE) -> Work in progress | Y16: =VLOOKUP(Table_query__64[[#This Row],[Nr]],'MyTracker Export'!A:Z,'MyTracker Export'!$Z$1,FALSE) -> Ali TRIGUI | Z16: =VLOOKUP(Table_query__64[[#This Row],[Nr]],'MyTracker Export'!A:AA,'MyTracker Export'!$AA$1,FALSE) -> Wissem Bensaid | AB16: =IF(Table_query__64[[#This Row],[Project status]]=Table_query__64[[#This Row],[Project Status Check]],"OK","NOK") -> OK | AC16: =IF(Table_query__64[[#This Row],[PM]]=Table_query__64[[#This Row],[PM Check]],"OK","NOK") -> NOK | AD16: =IF(Table_query__64[[#This Row],[PP]]=Table_query__64[[#This Row],[Pilot Check]],"OK","NOK") -> OK
A17: O3566 | B17: WiTTE Automotive | C17: Witte Bg _PlantExtension | D17: IPS Bulgaria | E17: Other industry | F17: Work in progress | G17: 46083.042 | I17: Nevena Banova | J17: Nevena Banova | L17: Project Management;#1 | M17: Reimbursable | N17: Q8870 | O17: 0 | P17: 7845.8 | Q17: 2026 | T17: 2947 | U17: O3566 WiTTE Automotive Witte Bg _PlantExtension | V17: Item | W17: sites/Activity/Lists/GroupIPSProjects | X17: =VLOOKUP(Table_query__64[[#This Row],[Nr]],'MyTracker Export'!A:P,'MyTracker Export'!$P$1,FALSE) -> Work in progress | Y17: =VLOOKUP(Table_query__64[[#This Row],[Nr]],'MyTracker Export'!A:Z,'MyTracker Export'!$Z$1,FALSE) -> Nevena Banova | Z17: =VLOOKUP(Table_query__64[[#This Row],[Nr]],'MyTracker Export'!A:AA,'MyTracker Export'!$AA$1,FALSE) -> Nevena Banova | AB17: =IF(Table_query__64[[#This Row],[Project status]]=Table_query__64[[#This Row],[Project Status Check]],"OK","NOK") -> OK | AC17: =IF(Table_query__64[[#This Row],[PM]]=Table_query__64[[#This Row],[PM Check]],"OK","NOK") -> OK | AD17: =IF(Table_query__64[[#This Row],[PP]]=Table_query__64[[#This Row],[Pilot Check]],"OK","NOK") -> OK
A18: O3565 | B18: WiTTE Automotive | C18: Witte Bg _PlantExtension | D18: IPS Bulgaria | E18: Other industry | F18: Work in progress | G18: 46083.042 | I18: Nevena Banova | J18: Nevena Banova | L18: Project Management;#1;#Project Assistance;#73 | M18: Reimbursable | N18: Q8740 | O18: 0 | P18: 13238.4 | Q18: 2026 | T18: 2946 | U18: O3565 WiTTE Automotive Witte Bg _PlantExtension | V18: Item | W18: sites/Activity/Lists/GroupIPSProjects | X18: =VLOOKUP(Table_query__64[[#This Row],[Nr]],'MyTracker Export'!A:P,'MyTracker Export'!$P$1,FALSE) -> Work in progress | Y18: =VLOOKUP(Table_query__64[[#This Row],[Nr]],'MyTracker Export'!A:Z,'MyTracker Export'!$Z$1,FALSE) -> Nevena Banova | Z18: =VLOOKUP(Table_query__64[[#This Row],[Nr]],'MyTracker Export'!A:AA,'MyTracker Export'!$AA$1,FALSE) -> Nevena Banova | AB18: =IF(Table_query__64[[#This Row],[Project status]]=Table_query__64[[#This Row],[Project Status Check]],"OK","NOK") -> OK | AC18: =IF(Table_query__64[[#This Row],[PM]]=Table_query__64[[#This Row],[PM Check]],"OK","NOK") -> OK | AD18: =IF(Table_query__64[[#This Row],[PP]]=Table_query__64[[#This Row],[Pilot Check]],"OK","NOK") -> OK
A19: O3564 | B19: Mondelez GmbH Lörrach | C19: HSE Standards | D19: Group-IPS | E19: Food & Beverages | F19: Work in progress | G19: 46080.042 | I19: Jan Beske | J19: Yannick Vega | L19: Project Management;#1 | M19: Reimbursable | N19: Q9147 | O19: 1 | P19: 116002 | Q19: 2026 | T19: 2945 | U19: O3564 Mondelez GmbH Lörrach HSE Standards | V19: Item | W19: sites/Activity/Lists/GroupIPSProjects | X19: =VLOOKUP(Table_query__64[[#This Row],[Nr]],'MyTracker Export'!A:P,'MyTracker Export'!$P$1,FALSE) -> Work in progress | Y19: =VLOOKUP(Table_query__64[[#This Row],[Nr]],'MyTracker Export'!A:Z,'MyTracker Export'!$Z$1,FALSE) -> Jan Beske | Z19: =VLOOKUP(Table_query__64[[#This Row],[Nr]],'MyTracker Export'!A:AA,'MyTracker Export'!$AA$1,FALSE) -> Yannick Vega Fernandez | AB19: =IF(Table_query__64[[#This Row],[Project status]]=Table_query__64[[#This Row],[Project Status Check]],"OK","NOK") -> OK | AC19: =IF(Table_query__64[[#This Row],[PM]]=Table_query__64[[#This Row],[PM Check]],"OK","NOK") -> OK | AD19: =IF(Table_query__64[[#This Row],[PP]]=Table_query__64[[#This Row],[Pilot Check]],"OK","NOK") -> NOK
A20: O3563 | B20: Evonik Antwerpen N.V. | C20: FK_D763 Str eng concr. floor | D20: IPS Belgium | E20: Chemicals | F20: Work in progress | G20: 46080.042 | I20: Charlélie Michel | J20: Peter Holvoet | K20: Sophie Saussu | L20: Project Management;#1;#Engineering;#7 | M20: Reimbursable | N20: Q9119 | O20: 0.3 | P20: 15742.35 | Q20: 2026 | T20: 2944 | U20: O3563 Evonik Antwerpen N.V. FK_D763 Str eng concr. floor | V20: Item | W20: sites/Activity/Lists/GroupIPSProjects | X20: =VLOOKUP(Table_query__64[[#This Row],[Nr]],'MyTracker Export'!A:P,'MyTracker Export'!$P$1,FALSE) -> Work in progress | Y20: =VLOOKUP(Table_query__64[[#This Row],[Nr]],'MyTracker Export'!A:Z,'MyTracker Export'!$Z$1,FALSE) -> Charlélie Michel | Z20: =VLOOKUP(Table_query__64[[#This Row],[Nr]],'MyTracker Export'!A:AA,'MyTracker Export'!$AA$1,FALSE) -> Peter Holvoet | AB20: =IF(Table_query__64[[#This Row],[Project status]]=Table_query__64[[#This Row],[Project Status Check]],"OK","NOK") -> OK | AC20: =IF(Table_query__64[[#This Row],[PM]]=Table_query__64[[#This Row],[PM Check]],"OK","NOK") -> OK | AD20: =IF(Table_query__64[[#This Row],[PP]]=Table_query__64[[#This Row],[Pilot Check]],"OK","NOK") -> OK
A21: O3562 | B21: Connecting visions | C21: Industrial Laundry BILBAO | D21: IPS Spain | E21: Other industry | F21: Work in progress | G21: 46078.042 | I21: Maria Romero | J21: Miguel Menéndez | L21: Consulting;#2 | M21: Lump sum | N21: Q9180 | O21: 1 | P21: 8694 | Q21: 2026 | T21: 2943 | U21: O3562 Connecting visions Industrial Laundry BILBAO | V21: Item | W21: sites/Activity/Lists/GroupIPSProjects | X21: =VLOOKUP(Table_query__64[[#This Row],[Nr]],'MyTracker Export'!A:P,'MyTracker Export'!$P$1,FALSE) -> Work in progress | Y21: =VLOOKUP(Table_query__64[[#This Row],[Nr]],'MyTracker Export'!A:Z,'MyTracker Export'!$Z$1,FALSE) -> Maria Romero | Z21: =VLOOKUP(Table_query__64[[#This Row],[Nr]],'MyTracker Export'!A:AA,'MyTracker Export'!$AA$1,FALSE) -> Miguel Menéndez | AB21: =IF(Table_query__64[[#This Row],[Project status]]=Table_query__64[[#This Row],[Project Status Check]],"OK","NOK") -> OK | AC21: =IF(Table_query__64[[#This Row],[PM]]=Table_query__64[[#This Row],[PM Check]],"OK","NOK") -> OK | AD21: =IF(Table_query__64[[#This Row],[PP]]=Table_query__64[[#This Row],[Pilot Check]],"OK","NOK") -> OK
A22: O3561 | B22: Affinity Factory _ Spain | C22: VSU Sistema 7 | D22: IPS Spain | E22: Food & Beverages | F22: Finished | G22: 46078.042 | H22: 46078.042 | I22: Maria Bonaccio | J22: Maria Bonaccio | L22: Project Management;#1 | M22: Reimbursable | N22: Q9059 | O22: 0 | P22: 0 | Q22: 2026 | R22: 2026 | T22: 2942 | U22: O3561 Affinity Factory _ Spain VSU Sistema 7 | V22: Item | W22: sites/Activity/Lists/GroupIPSProjects | X22: =VLOOKUP(Table_query__64[[#This Row],[Nr]],'MyTracker Export'!A:P,'MyTracker Export'!$P$1,FALSE) -> Finished | Y22: =VLOOKUP(Table_query__64[[#This Row],[Nr]],'MyTracker Export'!A:Z,'MyTracker Export'!$Z$1,FALSE) -> Maria Bonaccio | Z22: =VLOOKUP(Table_query__64[[#This Row],[Nr]],'MyTracker Export'!A:AA,'MyTracker Export'!$AA$1,FALSE) -> Maria Bonaccio | AB22: =IF(Table_query__64[[#This Row],[Project status]]=Table_query__64[[#This Row],[Project Status Check]],"OK","NOK") -> OK | AC22: =IF(Table_query__64[[#This Row],[PM]]=Table_query__64[[#This Row],[PM Check]],"OK","NOK") -> OK | AD22: =IF(Table_query__64[[#This Row],[PP]]=Table_query__64[[#This Row],[Pilot Check]],"OK","NOK") -> OK
A23: O3560 | B23: ARCADE | C23: ARCADE 2026 | D23: Arquid | E23: Other industry | F23: Work in progress | G23: 46077.042 | I23: Rubén Gutiérrez Llamas | J23: Felipe Langa Hernáez | L23: Architecture;#5 | M23: Lump sum | N23: Q9211 | O23: 0 | P23: 0 | Q23: 2026 | T23: 2941 | U23: O3560 ARCADE ARCADE 2026 | V23: Item | W23: sites/Activity/Lists/GroupIPSProjects | X23: =VLOOKUP(Table_query__64[[#This Row],[Nr]],'MyTracker Export'!A:P,'MyTracker Export'!$P$1,FALSE) -> Work in progress | Y23: =VLOOKUP(Table_query__64[[#This Row],[Nr]],'MyTracker Export'!A:Z,'MyTracker Export'!$Z$1,FALSE) -> Rubén Gutiérrez Llamas | Z23: =VLOOKUP(Table_query__64[[#This Row],[Nr]],'MyTracker Export'!A:AA,'MyTracker Export'!$AA$1,FALSE) -> Felipe Langa Hernáez | AB23: =IF(Table_query__64[[#This Row],[Project status]]=Table_query__64[[#This Row],[Project Status Check]],"OK","NOK") -> OK | AC23: =IF(Table_query__64[[#This Row],[PM]]=Table_query__64[[#This Row],[PM Check]],"OK","NOK") -> OK | AD23: =IF(Table_query__64[[#This Row],[PP]]=Table_query__64[[#This Row],[Pilot Check]],"OK","NOK") -> OK
A24: O3559 | B24: MARETAP | C24: EM4930_Etd remplac séparateur | D24: IAPS Tunisia | E24: Chemicals | F24: Work in progress | G24: 46073.042 | I24: Wissem Bensaid | J24: Wissem Bensaid | L24: Project Management;#1;#Engineering;#7;#Mechanical Engineering;#15;#Piping Engineering;#16;#Process Engineering;#17 | M24: Lump sum | N24: Q9205 | O24: 0 | P24: 25000 | Q24: 2026 | T24: 2940 | U24: O3559 MARETAP EM4930_Etd remplac séparateur | V24: Item | W24: sites/Activity/Lists/GroupIPSProjects | X24: =VLOOKUP(Table_query__64[[#This Row],[Nr]],'MyTracker Export'!A:P,'MyTracker Export'!$P$1,FALSE) -> Work in progress | Y24: =VLOOKUP(Table_query__64[[#This Row],[Nr]],'MyTracker Export'!A:Z,'MyTracker Export'!$Z$1,FALSE) -> Taha Elghith | Z24: =VLOOKUP(Table_query__64[[#This Row],[Nr]],'MyTracker Export'!A:AA,'MyTracker Export'!$AA$1,FALSE) -> Wissem Bensaid | AB24: =IF(Table_query__64[[#This Row],[Project status]]=Table_query__64[[#This Row],[Project Status Check]],"OK","NOK") -> OK | AC24: =IF(Table_query__64[[#This Row],[PM]]=Table_query__64[[#This Row],[PM Check]],"OK","NOK") -> NOK | AD24: =IF(Table_query__64[[#This Row],[PP]]=Table_query__64[[#This Row],[Pilot Check]],"OK","NOK") -> OK
A25: O3558 | B25: Ineos Feluy SA | C25: MS project planning TAR | D25: IPS Belgium | E25: Chemicals | F25: Work in progress | G25: 46072.042 | I25: Niels Van Osselaer | J25: Peter Holvoet | K25: Julie Pollet | L25: Project Management;#1;#Project Assistance;#73 | M25: Reimbursable | N25: Q9165 | O25: 0.5 | P25: 15088.37 | Q25: 2026 | T25: 2939 | U25: O3558 Ineos Feluy SA MS project planning TAR | V25: Item | W25: sites/Activity/Lists/GroupIPSProjects | X25: =VLOOKUP(Table_query__64[[#This Row],[Nr]],'MyTracker Export'!A:P,'MyTracker Export'!$P$1,FALSE) -> Work in progress | Y25: =VLOOKUP(Table_query__64[[#This Row],[Nr]],'MyTracker Export'!A:Z,'MyTracker Export'!$Z$1,FALSE) -> Niels Van Osselaer | Z25: =VLOOKUP(Table_query__64[[#This Row],[Nr]],'MyTracker Export'!A:AA,'MyTracker Export'!$AA$1,FALSE) -> Peter Holvoet | AB25: =IF(Table_query__64[[#This Row],[Project status]]=Table_query__64[[#This Row],[Project Status Check]],"OK","NOK") -> OK | AC25: =IF(Table_query__64[[#This Row],[PM]]=Table_query__64[[#This Row],[PM Check]],"OK","NOK") -> OK | AD25: =IF(Table_query__64[[#This Row],[PP]]=Table_query__64[[#This Row],[Pilot Check]],"OK","NOK") -> OK
A26: O3557 | B26: 2Valorise Amel S.A. | C26: Safety & CS Support_shutdown | D26: IPS Belgium | E26: Primary & Metals | F26: Work in progress | G26: 46072.042 | I26: Guy Melis | J26: Jurgen Van Den Driessche | L26: Project Management;#1;#Safety & Site Supervision;#78 | M26: Reimbursable | N26: Q9114 | O26: 1 | P26: 45855 | Q26: 2026 | T26: 2938 | U26: O3557 2Valorise Amel S.A. Safety & CS Support_shutdown | V26: Item | W26: sites/Activity/Lists/GroupIPSProjects | X26: =VLOOKUP(Table_query__64[[#This Row],[Nr]],'MyTracker Export'!A:P,'MyTracker Export'!$P$1,FALSE) -> Work in progress | Y26: =VLOOKUP(Table_query__64[[#This Row],[Nr]],'MyTracker Export'!A:Z,'MyTracker Export'!$Z$1,FALSE) -> Guy Melis | Z26: =VLOOKUP(Table_query__64[[#This Row],[Nr]],'MyTracker Export'!A:AA,'MyTracker Export'!$AA$1,FALSE) -> Jurgen Van Den Driessche | AB26: =IF(Table_query__64[[#This Row],[Project status]]=Table_query__64[[#This Row],[Project Status Check]],"OK","NOK") -> OK | AC26: =IF(Table_query__64[[#This Row],[PM]]=Table_query__64[[#This Row],[PM Check]],"OK","NOK") -> OK | AD26: =IF(Table_query__64[[#This Row],[PP]]=Table_query__64[[#This Row],[Pilot Check]],"OK","NOK") -> OK
A27: O3556 | B27: ArcelorMittal Esch-Belval | C27: Dedusting AM Belval TMB | D27: IPS Belgium | E27: Primary & Metals | F27: Work in progress | G27: 46072.042 | I27: Denis Remacle | J27: Denis Remacle | K27: Amandyne Rosart | L27: Project Management;#1;#Engineering;#7;#Process Engineering;#17 | M27: Reimbursable | N27: Q9067 | O27: 0.01 | P27: 11582.11 | Q27: 2026 | T27: 2937 | U27: O3556 ArcelorMittal Esch-Belval Dedusting AM Belval TMB | V27: Item | W27: sites/Activity/Lists/GroupIPSProjects | X27: =VLOOKUP(Table_query__64[[#This Row],[Nr]],'MyTracker Export'!A:P,'MyTracker Export'!$P$1,FALSE) -> Work in progress | Y27: =VLOOKUP(Table_query__64[[#This Row],[Nr]],'MyTracker Export'!A:Z,'MyTracker Export'!$Z$1,FALSE) -> Denis Remacle | Z27: =VLOOKUP(Table_query__64[[#This Row],[Nr]],'MyTracker Export'!A:AA,'MyTracker Export'!$AA$1,FALSE) -> Denis Remacle | AB27: =IF(Table_query__64[[#This Row],[Project status]]=Table_query__64[[#This Row],[Project Status Check]],"OK","NOK") -> OK | AC27: =IF(Table_query__64[[#This Row],[PM]]=Table_query__64[[#This Row],[PM Check]],"OK","NOK") -> OK | AD27: =IF(Table_query__64[[#This Row],[PP]]=Table_query__64[[#This Row],[Pilot Check]],"OK","NOK") -> OK
A28: O3555 | B28: SANITECHNIEK | C28: EM4946_Prépration Plan Fluide | D28: IAPS Tunisia | E28: Buildings | F28: Work in progress | G28: 46072.042 | I28: Wissem Bensaid | J28: Wissem Bensaid | L28: Project Management;#1;#Engineering;#7;#Engineering Coordination;#54 | M28: Reimbursable | N28: Q9202 | O28: 0 | P28: 8000 | Q28: 2026 | T28: 2936 | U28: O3555 SANITECHNIEK EM4946_Prépration Plan Fluide | V28: Item | W28: sites/Activity/Lists/GroupIPSProjects | X28: =VLOOKUP(Table_query__64[[#This Row],[Nr]],'MyTracker Export'!A:P,'MyTracker Export'!$P$1,FALSE) -> Work in progress | Y28: =VLOOKUP(Table_query__64[[#This Row],[Nr]],'MyTracker Export'!A:Z,'MyTracker Export'!$Z$1,FALSE) -> Lamiss Derbel | Z28: =VLOOKUP(Table_query__64[[#This Row],[Nr]],'MyTracker Export'!A:AA,'MyTracker Export'!$AA$1,FALSE) -> Wissem Bensaid | AB28: =IF(Table_query__64[[#This Row],[Project status]]=Table_query__64[[#This Row],[Project Status Check]],"OK","NOK") -> OK | AC28: =IF(Table_query__64[[#This Row],[PM]]=Table_query__64[[#This Row],[PM Check]],"OK","NOK") -> NOK | AD28: =IF(Table_query__64[[#This Row],[PP]]=Table_query__64[[#This Row],[Pilot Check]],"OK","NOK") -> OK
A29: O3554 | B29: GlaxoSmithKline Biologicals Wavre | C29: C&Q Cuves Mobiles WN10 | D29: IPS Belgium | E29: Life Sciences | F29: Work in progress | G29: 46071.042 | I29: Yves Debaisieux | J29: Loïc Bouvier | K29: Céline Lechado | L29: Project Management;#1 | M29: Lump sum | N29: Q9054 | O29: 2 | P29: 121800 | Q29: 2026 | T29: 2935 | U29: O3554 GlaxoSmithKline C&Q Cuves Mobiles WN10 | V29: Item | W29: sites/Activity/Lists/GroupIPSProjects | X29: =VLOOKUP(Table_query__64[[#This Row],[Nr]],'MyTracker Export'!A:P,'MyTracker Export'!$P$1,FALSE) -> Work in progress | Y29: =VLOOKUP(Table_query__64[[#This Row],[Nr]],'MyTracker Export'!A:Z,'MyTracker Export'!$Z$1,FALSE) -> Yves Debaisieux | Z29: =VLOOKUP(Table_query__64[[#This Row],[Nr]],'MyTracker Export'!A:AA,'MyTracker Export'!$AA$1,FALSE) -> Loïc Bouvier | AB29: =IF(Table_query__64[[#This Row],[Project status]]=Table_query__64[[#This Row],[Project Status Check]],"OK","NOK") -> OK | AC29: =IF(Table_query__64[[#This Row],[PM]]=Table_query__64[[#This Row],[PM Check]],"OK","NOK") -> OK | AD29: =IF(Table_query__64[[#This Row],[PP]]=Table_query__64[[#This Row],[Pilot Check]],"OK","NOK") -> OK
A30: O3553 | B30: SANITECHNIEK | C30: EM4922_Projeteur HVAC | D30: IAPS Tunisia | E30: Buildings | F30: Work in progress | G30: 46069.042 | I30: Wissem Bensaid | J30: Wissem Bensaid | L30: Project Management;#1 | M30: Reimbursable | N30: Q9192 | O30: 0 | P30: 6400 | Q30: 2026 | T30: 2934 | U30: O3553 SANITECHNIEK EM4922_Projeteur HVAC | V30: Item | W30: sites/Activity/Lists/GroupIPSProjects | X30: =VLOOKUP(Table_query__64[[#This Row],[Nr]],'MyTracker Export'!A:P,'MyTracker Export'!$P$1,FALSE) -> Work in progress | Y30: =VLOOKUP(Table_query__64[[#This Row],[Nr]],'MyTracker Export'!A:Z,'MyTracker Export'!$Z$1,FALSE) -> Hanen GABSI | Z30: =VLOOKUP(Table_query__64[[#This Row],[Nr]],'MyTracker Export'!A:AA,'MyTracker Export'!$AA$1,FALSE) -> Wissem Bensaid | AB30: =IF(Table_query__64[[#This Row],[Project status]]=Table_query__64[[#This Row],[Project Status Check]],"OK","NOK") -> OK | AC30: =IF(Table_query__64[[#This Row],[PM]]=Table_query__64[[#This Row],[PM Check]],"OK","NOK") -> NOK | AD30: =IF(Table_query__64[[#This Row],[PP]]=Table_query__64[[#This Row],[Pilot Check]],"OK","NOK") -> OK
A31: O3552 | B31: Mondelez GmbH Lörrach | C31: Project Engineer external | D31: Group-IPS | E31: Food & Beverages | F31: Work in progress | G31: 46069.042 | I31: Fiete Heinrich | J31: Yannick Vega | K31: Yasmine Ben Rhaiem | L31: Project Management;#1 | M31: Reimbursable | N31: Q9191 | O31: 0 | P31: 44000 | Q31: 2026 | T31: 2933 | U31: O3552 Mondelez GmbH Lörrach Project Engineer external | V31: Item | W31: sites/Activity/Lists/GroupIPSProjects | X31: =VLOOKUP(Table_query__64[[#This Row],[Nr]],'MyTracker Export'!A:P,'MyTracker Export'!$P$1,FALSE) -> Work in progress | Y31: =VLOOKUP(Table_query__64[[#This Row],[Nr]],'MyTracker Export'!A:Z,'MyTracker Export'!$Z$1,FALSE) -> Fiete Heinrich | Z31: =VLOOKUP(Table_query__64[[#This Row],[Nr]],'MyTracker Export'!A:AA,'MyTracker Export'!$AA$1,FALSE) -> Yannick Vega Fernandez | AB31: =IF(Table_query__64[[#This Row],[Project status]]=Table_query__64[[#This Row],[Project Status Check]],"OK","NOK") -> OK | AC31: =IF(Table_query__64[[#This Row],[PM]]=Table_query__64[[#This Row],[PM Check]],"OK","NOK") -> OK | AD31: =IF(Table_query__64[[#This Row],[PP]]=Table_query__64[[#This Row],[Pilot Check]],"OK","NOK") -> NOK
A32: O3551 | B32: VEMAK | C32: EM4866_LNG Terminal Project | D32: IAPS Tunisia | E32: Chemicals | F32: Work in progress | G32: 46069.042 | I32: Wissem Bensaid | J32: Wissem Bensaid | L32: Project Management;#1;#Engineering;#7;#Mechanical Engineering;#15;#Piping Engineering;#16;#Process Engineering;#17 | M32: Lump sum | N32: Q9167 | O32: 0 | P32: 251915.4 | Q32: 2026 | T32: 2932 | U32: O3551 VEMAK EM4866_LNG Terminal Project | V32: Item | W32: sites/Activity/Lists/GroupIPSProjects | X32: =VLOOKUP(Table_query__64[[#This Row],[Nr]],'MyTracker Export'!A:P,'MyTracker Export'!$P$1,FALSE) -> Work in progress | Y32: =VLOOKUP(Table_query__64[[#This Row],[Nr]],'MyTracker Export'!A:Z,'MyTracker Export'!$Z$1,FALSE) -> Omar Tounsi | Z32: =VLOOKUP(Table_query__64[[#This Row],[Nr]],'MyTracker Export'!A:AA,'MyTracker Export'!$AA$1,FALSE) -> Wissem Bensaid | AB32: =IF(Table_query__64[[#This Row],[Project status]]=Table_query__64[[#This Row],[Project Status Check]],"OK","NOK") -> OK | AC32: =IF(Table_query__64[[#This Row],[PM]]=Table_query__64[[#This Row],[PM Check]],"OK","NOK") -> NOK | AD32: =IF(Table_query__64[[#This Row],[PP]]=Table_query__64[[#This Row],[Pilot Check]],"OK","NOK") -> OK
A33: O3550 | B33: The British School | C33: Realization Phase 1 BSB | D33: Group-IPS | E33: Buildings | F33: Work in progress | G33: 46069.042 | I33: Corto Tristan Travada | J33: Juan Juarez | K33: Delphine Myllecan | L33: Project Management;#1;#Consulting;#2;#Architecture;#5;#Engineering;#7;#Construction Management;#42;#Project Assistance;#73;#Safety & Site Supervision;#78;#Safety Coordination;#80 | M33: Lump sum | N33: Q9173 | O33: 35 | P33: 1653632 | Q33: 2026 | T33: 2931 | U33: O3550 The British School Realization Phase 1 BSB | V33: Item | W33: sites/Activity/Lists/GroupIPSProjects | X33: =VLOOKUP(Table_query__64[[#This Row],[Nr]],'MyTracker Export'!A:P,'MyTracker Export'!$P$1,FALSE) -> Work in progress | Y33: =VLOOKUP(Table_query__64[[#This Row],[Nr]],'MyTracker Export'!A:Z,'MyTracker Export'!$Z$1,FALSE) -> Corto Tristan Travada | Z33: =VLOOKUP(Table_query__64[[#This Row],[Nr]],'MyTracker Export'!A:AA,'MyTracker Export'!$AA$1,FALSE) -> Juan Juarez Quintana | AB33: =IF(Table_query__64[[#This Row],[Project status]]=Table_query__64[[#This Row],[Project Status Check]],"OK","NOK") -> OK | AC33: =IF(Table_query__64[[#This Row],[PM]]=Table_query__64[[#This Row],[PM Check]],"OK","NOK") -> OK | AD33: =IF(Table_query__64[[#This Row],[PP]]=Table_query__64[[#This Row],[Pilot Check]],"OK","NOK") -> NOK
A34: O3549 | B34: Groupe OCP | C34: EM4872_Elec&Mechanical PM | D34: IAPS Tunisia | E34: Chemicals | F34: Work in progress | G34: 46069.042 | I34: Wissem Bensaid | J34: Wissem Bensaid | L34: Project Management;#1 | M34: Lump sum | N34: Q9189 | O34: 0 | P34: 70400 | Q34: 2026 | T34: 2930 | U34: O3549 Groupe OCP EM4872_Elec&Mechanical PM | V34: Item | W34: sites/Activity/Lists/GroupIPSProjects | X34: =VLOOKUP(Table_query__64[[#This Row],[Nr]],'MyTracker Export'!A:P,'MyTracker Export'!$P$1,FALSE) -> Work in progress | Y34: =VLOOKUP(Table_query__64[[#This Row],[Nr]],'MyTracker Export'!A:Z,'MyTracker Export'!$Z$1,FALSE) -> Zied Maghrebi | Z34: =VLOOKUP(Table_query__64[[#This Row],[Nr]],'MyTracker Export'!A:AA,'MyTracker Export'!$AA$1,FALSE) -> Wissem Bensaid | AB34: =IF(Table_query__64[[#This Row],[Project status]]=Table_query__64[[#This Row],[Project Status Check]],"OK","NOK") -> OK | AC34: =IF(Table_query__64[[#This Row],[PM]]=Table_query__64[[#This Row],[PM Check]],"OK","NOK") -> NOK | AD34: =IF(Table_query__64[[#This Row],[PP]]=Table_query__64[[#This Row],[Pilot Check]],"OK","NOK") -> OK
A35: O3548 | B35: SCG Gabes | C35: EM4899_Etude servomoteur | D35: IAPS Tunisia | E35: Primary & Metals | F35: Work in progress | G35: 46069.042 | I35: Wissem Bensaid | J35: Wissem Bensaid | L35: Project Management;#1;#Engineering;#7;#Mechanical Engineering;#15 | M35: Lump sum | N35: Q9188 | O35: 0 | P35: 4363.64 | Q35: 2026 | T35: 2929 | U35: O3548 SCG Gabes EM4899_Etude servomoteur | V35: Item | W35: sites/Activity/Lists/GroupIPSProjects | X35: =VLOOKUP(Table_query__64[[#This Row],[Nr]],'MyTracker Export'!A:P,'MyTracker Export'!$P$1,FALSE) -> Work in progress | Y35: =VLOOKUP(Table_query__64[[#This Row],[Nr]],'MyTracker Export'!A:Z,'MyTracker Export'!$Z$1,FALSE) -> Zied Maghrebi | Z35: =VLOOKUP(Table_query__64[[#This Row],[Nr]],'MyTracker Export'!A:AA,'MyTracker Export'!$AA$1,FALSE) -> Wissem Bensaid | AB35: =IF(Table_query__64[[#This Row],[Project status]]=Table_query__64[[#This Row],[Project Status Check]],"OK","NOK") -> OK | AC35: =IF(Table_query__64[[#This Row],[PM]]=Table_query__64[[#This Row],[PM Check]],"OK","NOK") -> NOK | AD35: =IF(Table_query__64[[#This Row],[PP]]=Table_query__64[[#This Row],[Pilot Check]],"OK","NOK") -> OK
A36: O3547 | B36: SCG Gabes | C36: EM4749_Plan As-Built | D36: IAPS Tunisia | E36: Primary & Metals | F36: Work in progress | G36: 46069.042 | I36: Wissem Bensaid | J36: Wissem Bensaid | L36: Project Management;#1;#Engineering;#7;#Piping Engineering;#16 | M36: Lump sum | N36: Q9186 | O36: 0 | P36: 7871.52 | Q36: 2026 | T36: 2928 | U36: O3547 SCG Gabes EM4749_Plan As-Built | V36: Item | W36: sites/Activity/Lists/GroupIPSProjects | X36: =VLOOKUP(Table_query__64[[#This Row],[Nr]],'MyTracker Export'!A:P,'MyTracker Export'!$P$1,FALSE) -> Work in progress | Y36: =VLOOKUP(Table_query__64[[#This Row],[Nr]],'MyTracker Export'!A:Z,'MyTracker Export'!$Z$1,FALSE) -> Zied Maghrebi | Z36: =VLOOKUP(Table_query__64[[#This Row],[Nr]],'MyTracker Export'!A:AA,'MyTracker Export'!$AA$1,FALSE) -> Wissem Bensaid | AB36: =IF(Table_query__64[[#This Row],[Project status]]=Table_query__64[[#This Row],[Project Status Check]],"OK","NOK") -> OK | AC36: =IF(Table_query__64[[#This Row],[PM]]=Table_query__64[[#This Row],[PM Check]],"OK","NOK") -> NOK | AD36: =IF(Table_query__64[[#This Row],[PP]]=Table_query__64[[#This Row],[Pilot Check]],"OK","NOK") -> OK
A37: O3546 | B37: TPS | C37: EM4867_Root causes analysis | D37: IAPS Tunisia | E37: Chemicals | F37: Work in progress | G37: 46069.042 | I37: Wissem Bensaid | J37: Wissem Bensaid | L37: Project Management;#1 | M37: Lump sum | N37: Q9187 | O37: 0 | P37: 2100 | Q37: 2026 | T37: 2927 | U37: O3546 TPS EM4867_Root causes analysis | V37: Item | W37: sites/Activity/Lists/GroupIPSProjects | X37: =VLOOKUP(Table_query__64[[#This Row],[Nr]],'MyTracker Export'!A:P,'MyTracker Export'!$P$1,FALSE) -> Work in progress | Y37: =VLOOKUP(Table_query__64[[#This Row],[Nr]],'MyTracker Export'!A:Z,'MyTracker Export'!$Z$1,FALSE) -> Zied Maghrebi | Z37: =VLOOKUP(Table_query__64[[#This Row],[Nr]],'MyTracker Export'!A:AA,'MyTracker Export'!$AA$1,FALSE) -> Wissem Bensaid | AB37: =IF(Table_query__64[[#This Row],[Project status]]=Table_query__64[[#This Row],[Project Status Check]],"OK","NOK") -> OK | AC37: =IF(Table_query__64[[#This Row],[PM]]=Table_query__64[[#This Row],[PM Check]],"OK","NOK") -> NOK | AD37: =IF(Table_query__64[[#This Row],[PP]]=Table_query__64[[#This Row],[Pilot Check]],"OK","NOK") -> OK
A38: O3545 | B38: FIVES | C38: EM4910_3D & 2D de gaines | D38: IAPS Tunisia | E38: Primary & Metals | F38: Work in progress | G38: 46066.042 | I38: Wissem Bensaid | J38: Wissem Bensaid | L38: Project Management;#1;#Engineering;#7;#Mechanical Engineering;#15 | M38: Lump sum | N38: Q9185 | O38: 0 | P38: 7200 | Q38: 2026 | T38: 2926 | U38: O3545 FIVES EM4910_3D & 2D de gaines | V38: Item | W38: sites/Activity/Lists/GroupIPSProjects | X38: =VLOOKUP(Table_query__64[[#This Row],[Nr]],'MyTracker Export'!A:P,'MyTracker Export'!$P$1,FALSE) -> Work in progress | Y38: =VLOOKUP(Table_query__64[[#This Row],[Nr]],'MyTracker Export'!A:Z,'MyTracker Export'!$Z$1,FALSE) -> Souhir HAMMAMI | Z38: =VLOOKUP(Table_query__64[[#This Row],[Nr]],'MyTracker Export'!A:AA,'MyTracker Export'!$AA$1,FALSE) -> Wissem Bensaid | AB38: =IF(Table_query__64[[#This Row],[Project status]]=Table_query__64[[#This Row],[Project Status Check]],"OK","NOK") -> OK | AC38: =IF(Table_query__64[[#This Row],[PM]]=Table_query__64[[#This Row],[PM Check]],"OK","NOK") -> NOK | AD38: =IF(Table_query__64[[#This Row],[PP]]=Table_query__64[[#This Row],[Pilot Check]],"OK","NOK") -> OK
A39: O3544 | B39: Groupe OCP | C39: EM4472_ Descriptif Tech | D39: IAPS Tunisia | E39: Chemicals | F39: Work in progress | G39: 46066.042 | I39: Wissem Bensaid | J39: Wissem Bensaid | L39: Project Management;#1;#Engineering;#7;#Mechanical Engineering;#15 | M39: Lump sum | N39: Q9184 | O39: 0 | P39: 85876 | Q39: 2026 | T39: 2925 | U39: O3544 Groupe OCP EM4472_ Descriptif Tech | V39: Item | W39: sites/Activity/Lists/GroupIPSProjects | X39: =VLOOKUP(Table_query__64[[#This Row],[Nr]],'MyTracker Export'!A:P,'MyTracker Export'!$P$1,FALSE) -> Work in progress | Y39: =VLOOKUP(Table_query__64[[#This Row],[Nr]],'MyTracker Export'!A:Z,'MyTracker Export'!$Z$1,FALSE) -> Mansour Hamza | Z39: =VLOOKUP(Table_query__64[[#This Row],[Nr]],'MyTracker Export'!A:AA,'MyTracker Export'!$AA$1,FALSE) -> Wissem Bensaid | AB39: =IF(Table_query__64[[#This Row],[Project status]]=Table_query__64[[#This Row],[Project Status Check]],"OK","NOK") -> OK | AC39: =IF(Table_query__64[[#This Row],[PM]]=Table_query__64[[#This Row],[PM Check]],"OK","NOK") -> NOK | AD39: =IF(Table_query__64[[#This Row],[PP]]=Table_query__64[[#This Row],[Pilot Check]],"OK","NOK") -> OK
A40: O3543 | B40: FIVES | C40: EM4743_2 x CGL & CAGL in USA | D40: IAPS Tunisia | E40: Primary & Metals | F40: Work in progress | G40: 46066.042 | I40: Wissem Bensaid | J40: Wissem Bensaid | L40: Project Management;#1;#Engineering;#7;#Mechanical Engineering;#15 | M40: Lump sum | N40: Q9183 | O40: 0 | P40: 24842.98 | Q40: 2026 | T40: 2924 | U40: O3543 FIVES EM4743_2 x CGL & CAGL in USA | V40: Item | W40: sites/Activity/Lists/GroupIPSProjects | X40: =VLOOKUP(Table_query__64[[#This Row],[Nr]],'MyTracker Export'!A:P,'MyTracker Export'!$P$1,FALSE) -> Work in progress | Y40: =VLOOKUP(Table_query__64[[#This Row],[Nr]],'MyTracker Export'!A:Z,'MyTracker Export'!$Z$1,FALSE) -> Souhir HAMMAMI | Z40: =VLOOKUP(Table_query__64[[#This Row],[Nr]],'MyTracker Export'!A:AA,'MyTracker Export'!$AA$1,FALSE) -> Wissem Bensaid | AB40: =IF(Table_query__64[[#This Row],[Project status]]=Table_query__64[[#This Row],[Project Status Check]],"OK","NOK") -> OK | AC40: =IF(Table_query__64[[#This Row],[PM]]=Table_query__64[[#This Row],[PM Check]],"OK","NOK") -> NOK | AD40: =IF(Table_query__64[[#This Row],[PP]]=Table_query__64[[#This Row],[Pilot Check]],"OK","NOK") -> OK
...

Sheet MyTracker Export
A1: 1 | B1: 2 | C1: 3 | D1: 4 | E1: 5 | F1: 6 | G1: 7 | H1: 8 | I1: 9 | J1: 10 | K1: 11 | L1: 12 | M1: 13 | N1: 14 | O1: 15 | P1: 16 | Q1: 17 | R1: 18 | S1: 19 | T1: 20 | U1: 21 | V1: 22 | W1: 23 | X1: 24 | Y1: 25 | Z1: 26 | AA1: 27
A2: ProjectNumber | B2: Title | C2: ProjectDescription | D2: ProjectManager | E2: ProjectPilot | F2: ProjectAssistant | G2: CustomerLookup | H2: ProjectFinType | I2: ProjectStartDate | J2: ProjectCloseDate | K2: LastScopeChange | L2: LastScopeChangeValue | M2: LastScopeChangeResponsible | N2: NrOfScopeChange | O2: LastScopeChangeIndex | P2: ProjectStatusLookup | Q2: AreaLookup | R2: IndustryLookup | S2: ServiceLookup | T2: LegalEntityLookup | U2: SubLegalEntityLookup | V2: QuotationNumber | W2: CapEx | X2: SumBaseWorkScopes | Y2: ReferenceSheetLink | Z2: Project Manager | AA2: Project Pilot
A3: O3581 | B3: PE1051_BESS Project | D3: istabrak.frikha@group-ips.com | E3: wissem.bensaid@group-ips.com | G3: GOPA | H3: Lump sum | I3: 46098 | K3: 46098 | L3: 172000 | M3: wissem.bensaid@group-ips.com | N3: 0 | O3: 0 | P3: Work in progress | R3: Chemicals | S3: Engineering|Project Management|HVAC Engineering|Utilities Engineering | T3: IAPS Tunisia | U3: IAPS Tunisia | V3: Q9253 | W3: 0 | X3: 172000 | Z3: =VLOOKUP(D3,'ZOHO Export'!$H:$W,16,FALSE) -> Istabrak Frikha | AA3: =VLOOKUP(E3,'ZOHO Export'!$H:$W,16,FALSE) -> Wissem Bensaid
A4: O3580 | B4: P&ID Update Nuts connection | D4: audric.jeanne@group-ips.com | E4: karel.de.swert@group-ips.com | G4: Cargill Chocolate Belgium NV (Mouscron) | H4: Lump sum | I4: 46098 | K4: 46098 | L4: 828.09 | M4: audric.jeanne@group-ips.com | N4: 0 | O4: 0 | P4: Work in progress | R4: Food & Beverages | S4: Engineering|Project Management | T4: IPS Belgium | U4: IPS Belgium|IAPS Tunisia | V4: Q9213 | W4: 10000 | X4: 828.09 | Z4: =VLOOKUP(D4,'ZOHO Export'!$H:$W,16,FALSE) -> Audric Jeanne | AA4: =VLOOKUP(E4,'ZOHO Export'!$H:$W,16,FALSE) -> Karel De Swert
A5: O3579 | B5: BLIP OFFICES | D5: laura.cestau@group-ips.com | E5: laura.cestau@group-ips.com | G5: BLIP | H5: Lump sum | I5: 46097 | K5: 46097 | L5: 33957 | M5: laura.cestau@group-ips.com | N5: 0 | O5: 0 | P5: Work in progress | R5: Buildings | S5: Architecture|Project Management|Author's Supervision | T5: Arquid | U5: IPS Belgium|IPS Spain|Arquid | V5: Q9076 | W5: 20 | X5: 33957 | Z5: =VLOOKUP(D5,'ZOHO Export'!$H:$W,16,FALSE) -> Laura Cestau | AA5: =VLOOKUP(E5,'ZOHO Export'!$H:$W,16,FALSE) -> Laura Cestau
A6: O3578 | B6: PE1049_Guebiba water | D6: anouar.trigui@group-ips.com | E6: wissem.bensaid@group-ips.com | G6: TPS | H6: Lump sum | I6: 46093 | K6: 46093 | L6: 88827.9 | M6: wissem.bensaid@group-ips.com | N6: 0 | O6: 0 | P6: Work in progress | R6: Chemicals | S6: Engineering|Project Management|Mechanical Engineering|Piping Engineering|Process Engineering|Civil engineering|Structural engineering | T6: IAPS Tunisia | U6: IAPS Tunisia | V6: Q9247 | W6: 0 | X6: 88827.9 | Z6: =VLOOKUP(D6,'ZOHO Export'!$H:$W,16,FALSE) -> Anouar Trigui | AA6: =VLOOKUP(E6,'ZOHO Export'!$H:$W,16,FALSE) -> Wissem Bensaid
A7: O3577 | B7: Magor Land Conversion | D7: natalia.martinez.nieto@group-ips.com | E7: natalia.martinez.nieto@group-ips.com | G7: Ab InBev EU HQ (BEL Leuven) | H7: Lump sum | I7: 46093 | K7: 46093 | L7: 4492.65 | M7: natalia.martinez.nieto@group-ips.com | N7: 0 | O7: 0 | P7: Work in progress | R7: Food & Beverages | S7: Architecture | T7: Group-IPS | U7: IPS UK | V7: Q9240 | X7: 4492.65 | Z7: =VLOOKUP(D7,'ZOHO Export'!$H:$W,16,FALSE) -> Natalia Martínez Nieto | AA7: =VLOOKUP(E7,'ZOHO Export'!$H:$W,16,FALSE) -> Natalia Martínez Nieto
A8: O3576 | B8: Affinity Petcare CGM_STB | D8: maria.bonaccio@group-ips.com | E8: maria.bonaccio@group-ips.com | G8: Affinity Factory Italy | H8: Reimbursable | I8: 46090 | K8: 46090 | L8: 155932.13 | M8: maria.bonaccio@group-ips.com | N8: 0 | O8: 0 | P8: Work in progress | R8: Food & Beverages | S8: Project Management | T8: IPS Spain | U8: IPS Spain | V8: Q9151 | W8: 500000 | X8: 155932.13 | Z8: =VLOOKUP(D8,'ZOHO Export'!$H:$W,16,FALSE) -> Maria Bonaccio | AA8: =VLOOKUP(E8,'ZOHO Export'!$H:$W,16,FALSE) -> Maria Bonaccio
A9: O3575 | B9: Logistics / Customs | D9: maria.romero@group-ips.com | E9: josue.silverio@group-ips.com | F9: salma.gueblaoui@group-ips.com | G9: Albioma | H9: Reimbursable | I9: 46090 | K9: 46090 | L9: 15876 | M9: josue.silverio@group-ips.com | N9: 0 | O9: 0 | P9: Work in progress | R9: Chemicals | S9: Sustainable Process & Environment|Masterplan|Consulting | T9: IPS France | U9: IPS France | V9: Q9118 | W9: 350 | X9: 15876 | Z9: =VLOOKUP(D9,'ZOHO Export'!$H:$W,16,FALSE) -> Maria Romero | AA9: =VLOOKUP(E9,'ZOHO Export'!$H:$W,16,FALSE) -> Josué Silverio
A10: O3574 | B10: Leuven WH roof renovation | D10: valerie.codesido@group-ips.com | E10: lucas.soto@group-ips.com | G10: InBev Belgium BV | H10: Lump sum | I10: 46087 | K10: 46087 | L10: 25725.73 | M10: lucas.soto@group-ips.com | N10: 0 | O10: 0 | P10: Work in progress | R10: Food & Beverages | S10: Architecture|Engineering|Utilities Engineering|Structural engineering | T10: IPS Belgium | U10: IPS Belgium | V10: Q9236 | W10: 1.7 | X10: 25725.73 | Z10: =VLOOKUP(D10,'ZOHO Export'!$H:$W,16,FALSE) -> Valérie Codesido | AA10: =VLOOKUP(E10,'ZOHO Export'!$H:$W,16,FALSE) -> Lucas Soto
A11: O3573 | B11: GSK RX86 - Design and Built | C11: Realization phase with design & built | D11: mathias.martin@group-ips.com | E11: yves.debaisieux@group-ips.com | F11: celine.lechado@group-ips.com | G11: GlaxoSmithKline Biologicals Rixensart | H11: Lump sum | I11: 46087 | K11: 46087 | L11: 123937 | M11: loic.bouvier@group-ips.com | N11: 0 | O11: 0 | P11: Work in progress | R11: Life Sciences | S11: Engineering|Safety|Project Management|Project Quality Support Team|Construction Management|Engineering Coordination|Process Engineering|Project Assistance|Safety & Site Supervision|Utilities Engineering|Civil engineering | T11: IPS Belgium | U11: IPS Belgium | V11: Q9070 | W11: 1 | X11: 123937 | Z11: =VLOOKUP(D11,'ZOHO Export'!$H:$W,16,FALSE) -> Mathias Martin | AA11: =VLOOKUP(E11,'ZOHO Export'!$H:$W,16,FALSE) -> Yves Debaisieux
A12: O3572 | B12: Facility Single Line Diagram | D12: pranay.pawar@group-ips.com | E12: pranay.pawar@group-ips.com | G12: Tennant Solutions | H12: Lump sum | I12: 46085 | K12: 46085 | L12: 15454 | M12: pranay.pawar@group-ips.com | N12: 0 | O12: 0 | P12: Work in progress | R12: Primary & Metals | S12: Engineering | T12: IPS USA | U12: IPS USA | V12: Q9082 | W12: 0.01 | X12: 15454 | Z12: =VLOOKUP(D12,'ZOHO Export'!$H:$W,16,FALSE) -> Pranay Pawar | AA12: =VLOOKUP(E12,'ZOHO Export'!$H:$W,16,FALSE) -> Pranay Pawar
A13: O3571 | B13: EBS_Plot EPCM services | D13: nevena.banova@group-ips.com | E13: nevena.banova@group-ips.com | G13: Eberspaecher Bulgaria | H13: Lump sum | I13: 46085 | K13: 46085 | L13: 4780 | M13: nevena.banova@group-ips.com | N13: 0 | O13: 0 | P13: Work in progress | R13: Buildings | S13: Engineering|Project Management|Construction Management|Procurement|Civil engineering | T13: IPS Bulgaria | U13: IPS Bulgaria | V13: Q8653 | X13: 4780 | Z13: =VLOOKUP(D13,'ZOHO Export'!$H:$W,16,FALSE) -> Nevena Banova | AA13: =VLOOKUP(E13,'ZOHO Export'!$H:$W,16,FALSE) -> Nevena Banova
A14: O3570 | B14: Highbay Extension Leuven | D14: karel.de.swert@group-ips.com | E14: karel.de.swert@group-ips.com | G14: Ab InBev EU HQ (BEL Leuven) | H14: Lump sum | I14: 46085 | K14: 46085 | L14: 25046.95 | M14: karel.de.swert@group-ips.com | N14: 0 | O14: 0 | P14: Work in progress | R14: Food & Beverages | S14: Architecture|Engineering|Project Management|Masterplan|Consulting|Transaction services|Permitting | T14: IPS Belgium | U14: IPS Belgium | V14: Q9176 | X14: 25046.95 | Z14: =VLOOKUP(D14,'ZOHO Export'!$H:$W,16,FALSE) -> Karel De Swert | AA14: =VLOOKUP(E14,'ZOHO Export'!$H:$W,16,FALSE) -> Karel De Swert
A15: O3569 | B15: PE1046_Safi TSP Plant | D15: souhail.wali@group-ips.com | E15: wissem.bensaid@group-ips.com | G15: Fertinagro | H15: Lump sum | I15: 46085 | K15: 46085 | L15: 264000 | M15: wissem.bensaid@group-ips.com | N15: 0 | O15: 0 | P15: Work in progress | R15: Chemicals | S15: Project Management | T15: IAPS Tunisia | U15: IAPS Tunisia | V15: Q9223 | W15: 0 | X15: 264000 | Z15: =VLOOKUP(D15,'ZOHO Export'!$H:$W,16,FALSE) -> Souhail WALI | AA15: =VLOOKUP(E15,'ZOHO Export'!$H:$W,16,FALSE) -> Wissem Bensaid
A16: O3568 | B16: Viviendas Berrocales | D16: jaime.alvarez.perez@group-ips.com | E16: felipe.langa@group-ips.com | G16: Servicoop Management SL | H16: Lump sum | I16: 46084 | K16: 46084 | L16: 151188.6 | M16: felipe.langa@group-ips.com | N16: 0 | O16: 0 | P16: Work in progress | R16: Buildings | S16: Architecture|Engineering|Project Management|Utilities Engineering|Author's Supervision|Structural engineering | T16: Arquid | U16: IPS Spain|Arquid | V16: Q9130 | W16: 5 | X16: 151188.6 | Z16: =VLOOKUP(D16,'ZOHO Export'!$H:$W,16,FALSE) -> Jaime Álvarez Pérez | AA16: =VLOOKUP(E16,'ZOHO Export'!$H:$W,16,FALSE) -> Felipe Langa Hernáez
A17: O3567 | B17: PE1047_Storage & Pipeline | D17: ali.trigui@group-ips.com | E17: wissem.bensaid@group-ips.com | G17: Fertinagro | H17: Lump sum | I17: 46084 | K17: 46084 | L17: 66420 | M17: wissem.bensaid@group-ips.com | N17: 0 | O17: 0 | P17: Work in progress | R17: Chemicals | S17: Engineering|Project Management|Piping Engineering|Process Engineering | T17: IAPS Tunisia | U17: IAPS Tunisia | V17: Q9220 | W17: 0 | X17: 66420 | Z17: =VLOOKUP(D17,'ZOHO Export'!$H:$W,16,FALSE) -> Ali TRIGUI | AA17: =VLOOKUP(E17,'ZOHO Export'!$H:$W,16,FALSE) -> Wissem Bensaid
A18: O3566 | B18: Witte Bg _PlantExtension | D18: nevena.banova@group-ips.com | E18: nevena.banova@group-ips.com | G18: WiTTE Automotive | H18: Reimbursable | I18: 46083 | K18: 46083 | L18: 7845.8 | M18: nevena.banova@group-ips.com | N18: 0 | O18: 0 | P18: Work in progress | R18: Other industry | S18: Project Management | T18: IPS Bulgaria | U18: IPS Bulgaria | V18: Q8870 | X18: 7845.8 | Z18: =VLOOKUP(D18,'ZOHO Export'!$H:$W,16,FALSE) -> Nevena Banova | AA18: =VLOOKUP(E18,'ZOHO Export'!$H:$W,16,FALSE) -> Nevena Banova
A19: O3565 | B19: Witte Bg _PlantExtension | D19: nevena.banova@group-ips.com | E19: nevena.banova@group-ips.com | G19: WiTTE Automotive | H19: Reimbursable | I19: 46083 | K19: 46083 | L19: 13238.4 | M19: nevena.banova@group-ips.com | N19: 0 | O19: 0 | P19: Work in progress | R19: Other industry | S19: Digital Supply Chain & Operations|Project Management|Project Assistance | T19: IPS Bulgaria | U19: IPS Bulgaria | V19: Q8740 | X19: 13238.4 | Z19: =VLOOKUP(D19,'ZOHO Export'!$H:$W,16,FALSE) -> Nevena Banova | AA19: =VLOOKUP(E19,'ZOHO Export'!$H:$W,16,FALSE) -> Nevena Banova
A20: O3564 | B20: HSE Standards | C20: IPS will support the Mondelez HSE Department on the site in LÃ¶rrach - Germany in preparation and embedding of the safety standards on site. | D20: jan.beske@group-ips.com | E20: yannick.vega@group-ips.com | G20: Mondelez GmbH LÃ¶rrach | H20: Reimbursable | I20: 46080 | K20: 46080 | L20: 116002 | M20: yannick.vega@group-ips.com | N20: 0 | O20: 0 | P20: Work in progress | R20: Food & Beverages | S20: Project Management | T20: Group-IPS | U20: IPS Germany|Group-IPS | V20: Q9147 | W20: 1 | X20: 116002 | Z20: =VLOOKUP(D20,'ZOHO Export'!$H:$W,16,FALSE) -> Jan Beske | AA20: =VLOOKUP(E20,'ZOHO Export'!$H:$W,16,FALSE) -> Yannick Vega Fernandez
A21: O3563 | B21: FK_D763 Str eng concr. floor | D21: charlelie.michel@group-ips.com | E21: peter.holvoet@group-ips.com | F21: sophie.saussu@group-ips.com | G21: Evonik Antwerpen N.V. | H21: Reimbursable | I21: 46080 | K21: 46080 | L21: 15742.35 | M21: peter.holvoet@group-ips.com | N21: 0 | O21: 0 | P21: Work in progress | R21: Chemicals | S21: Engineering|Project Management|Structural engineering | T21: IPS Belgium | U21: IPS Belgium | V21: Q9119 | W21: 0.3 | X21: 15742.35 | Z21: =VLOOKUP(D21,'ZOHO Export'!$H:$W,16,FALSE) -> Charlélie Michel | AA21: =VLOOKUP(E21,'ZOHO Export'!$H:$W,16,FALSE) -> Peter Holvoet
A22: O3562 | B22: Industrial Laundry BILBAO | C22: TDD/EDD industrial laundry Bilbao for potential acquisition | D22: maria.romero@group-ips.com | E22: miguel.menendez@group-ips.com | G22: Connecting visions | H22: Lump sum | I22: 46078 | K22: 46078 | L22: 8694 | M22: maria.romero@group-ips.com | N22: 0 | O22: 0 | P22: Work in progress | R22: Other industry | S22: Sustainable Process & Environment|Consulting|Transaction services | T22: IPS Spain | U22: IPS Belgium|IPS Spain | V22: Q9180 | W22: 1 | X22: 8694 | Z22: =VLOOKUP(D22,'ZOHO Export'!$H:$W,16,FALSE) -> Maria Romero | AA22: =VLOOKUP(E22,'ZOHO Export'!$H:$W,16,FALSE) -> Miguel Menéndez
A23: O3561 | B23: VSU Sistema 7 | D23: maria.bonaccio@group-ips.com | E23: maria.bonaccio@group-ips.com | G23: Affinity Factory _ Spain | H23: Reimbursable | I23: 46078 | J23: 46078 | K23: 46097 | L23: -15704.81 | M23: maria.bonaccio@group-ips.com | N23: 1 | O23: 1 | P23: Finished | R23: Food & Beverages | S23: Project Management | T23: IPS Spain | U23: IPS Spain | V23: Q9059 | W23: 0 | X23: 0 | Z23: =VLOOKUP(D23,'ZOHO Export'!$H:$W,16,FALSE) -> Maria Bonaccio | AA23: =VLOOKUP(E23,'ZOHO Export'!$H:$W,16,FALSE) -> Maria Bonaccio
A24: O3560 | B24: ARCADE 2026 | D24: ruben.gutierrez@group-ips.com | E24: felipe.langa@group-ips.com | G24: ARCADE | H24: Lump sum | I24: 46077 | K24: 46077 | L24: 0 | M24: ruben.gutierrez@group-ips.com | N24: 0 | O24: 0 | P24: Work in progress | R24: Other industry | S24: Architecture | T24: Arquid | U24: Arquid | V24: Q9211 | W24: 0 | X24: 0 | Z24: =VLOOKUP(D24,'ZOHO Export'!$H:$W,16,FALSE) -> Rubén Gutiérrez Llamas | AA24: =VLOOKUP(E24,'ZOHO Export'!$H:$W,16,FALSE) -> Felipe Langa Hernáez
A25: O3559 | B25: PE1045_Etd remplac sÃ©parateur | D25: taha.elghith@group-ips.com | E25: wissem.bensaid@group-ips.com | G25: MARETAP | H25: Lump sum | I25: 46073 | K25: 46073 | L25: 25000 | M25: wissem.bensaid@group-ips.com | N25: 0 | O25: 0 | P25: Work in progress | R25: Chemicals | S25: Engineering|Project Management|Mechanical Engineering|Piping Engineering|Process Engineering|Procurement | T25: IAPS Tunisia | U25: IAPS Tunisia | V25: Q9205 | W25: 0 | X25: 25000 | Z25: =VLOOKUP(D25,'ZOHO Export'!$H:$W,16,FALSE) -> Taha Elghith | AA25: =VLOOKUP(E25,'ZOHO Export'!$H:$W,16,FALSE) -> Wissem Bensaid
